import asyncio
import logging
from unittest.mock import AsyncMock, MagicMock, patch

import pytest
from fastapi import HTTPException
from pymongo.errors import DuplicateKeyError, ServerSelectionTimeoutError


class TestErrorHandlingService:
    """Hata işleme servisleri için kapsamlı testler"""

    def test_database_connection_error_handling(self):
        """Veritabanı bağlantı hatası işleme testi"""
        from backend.database import get_async_db

        with patch("backend.database.get_async_db") as mock_db:
            mock_db.side_effect = ServerSelectionTimeoutError("Connection failed")

            # Hata durumunda uygun exception fırlatılmalı
            with pytest.raises(ServerSelectionTimeoutError):
                get_async_db()

    def test_duplicate_key_error_handling(self):
        """Duplicate key hatası işleme testi"""
        from backend.crud.job import create_job

        mock_db = AsyncMock()
        mock_collection = AsyncMock()
        mock_collection.insert_one.side_effect = DuplicateKeyError("Duplicate key")
        mock_db.jobs = mock_collection

        job_data = {"title": "Test Job", "company": "Test Corp"}

        # Duplicate key hatası uygun şekilde işlenmeli
        with pytest.raises(DuplicateKeyError):
            asyncio.run(create_job(mock_db, job_data))

    def test_validation_error_handling(self):
        """Validasyon hatası işleme testi"""
        from pydantic import ValidationError

        def validate_data(data):
            if not data.get("title"):
                raise ValidationError("Title is required")
            return data

        # Validasyon hatası uygun şekilde işlenmeli
        with pytest.raises(ValidationError):
            validate_data({})

    def test_authentication_error_handling(self):
        """Kimlik doğrulama hatası işleme testi"""
        from backend.utils.auth import verify_password

        # Geçersiz şifre ile kimlik doğrulama
        result = verify_password("wrong_password", "hashed_password")
        assert result is False

    def test_rate_limiting_error_handling(self):
        """Rate limiting hatası işleme testi"""
        from fastapi import HTTPException

        def check_rate_limit(user_id):
            # Simüle edilmiş rate limiting
            if user_id == "rate_limited_user":
                raise HTTPException(status_code=429, detail="Rate limit exceeded")
            return True

        # Rate limit aşıldığında uygun exception fırlatılmalı
        with pytest.raises(HTTPException) as exc_info:
            check_rate_limit("rate_limited_user")

        assert exc_info.value.status_code == 429

    def test_file_upload_error_handling(self):
        """Dosya yükleme hatası işleme testi"""
        import os

        def upload_file(file_path):
            if not os.path.exists(file_path):
                raise FileNotFoundError(f"File not found: {file_path}")
            return True

        # Dosya bulunamadığında uygun exception fırlatılmalı
        with pytest.raises(FileNotFoundError):
            upload_file("nonexistent_file.pdf")

    def test_external_api_error_handling(self):
        """Dış API hatası işleme testi"""
        import requests

        def call_external_api(url):
            try:
                response = requests.get(url, timeout=5)
                response.raise_for_status()
                return response.json()
            except requests.exceptions.RequestException as e:
                raise Exception(f"External API error: {str(e)}")

        # Dış API hatası uygun şekilde işlenmeli
        with pytest.raises(Exception):
            call_external_api("https://invalid-url-that-will-fail.com")

    def test_memory_error_handling(self):
        """Bellek hatası işleme testi"""

        def process_large_data(data_size):
            try:
                # Büyük veri işleme simülasyonu
                large_data = "x" * data_size
                return len(large_data)
            except MemoryError:
                raise Exception("Insufficient memory")

        # Bellek yetersizliği durumunda uygun exception fırlatılmalı
        with pytest.raises(Exception):
            process_large_data(10**9)  # 1GB veri

    def test_timeout_error_handling(self):
        """Timeout hatası işleme testi"""
        import asyncio

        async def long_running_task():
            await asyncio.sleep(10)  # 10 saniye süren işlem
            return "completed"

        async def execute_with_timeout():
            try:
                return await asyncio.wait_for(long_running_task(), timeout=1)
            except asyncio.TimeoutError:
                raise Exception("Operation timed out")

        # Timeout durumunda uygun exception fırlatılmalı
        with pytest.raises(Exception):
            asyncio.run(execute_with_timeout())

    def test_network_error_handling(self):
        """Ağ hatası işleme testi"""
        import socket

        def test_network_connection(host, port):
            try:
                sock = socket.socket(socket.AF_INET, socket.SOCK_STREAM)
                sock.settimeout(5)
                sock.connect((host, port))
                sock.close()
                return True
            except socket.error as e:
                raise Exception(f"Network error: {str(e)}")

        # Ağ hatası uygun şekilde işlenmeli
        with pytest.raises(Exception):
            test_network_connection("invalid-host", 9999)

    def test_logging_error_handling(self):
        """Logging hatası işleme testi"""
        import logging

        # Logging konfigürasyonu
        logging.basicConfig(level=logging.INFO)
        logger = logging.getLogger(__name__)

        def log_error_with_context(error, context):
            try:
                logger.error(f"Error in {context}: {str(error)}")
                return True
            except Exception as e:
                # Logging hatası durumunda fallback
                print(f"Logging failed: {str(e)}")
                return False

        # Logging hatası durumunda fallback çalışmalı
        result = log_error_with_context("Test error", "test_context")
        assert result is True

    def test_cascade_error_handling(self):
        """Kaskad hata işleme testi"""

        def level_3_function():
            raise ValueError("Level 3 error")

        def level_2_function():
            try:
                level_3_function()
            except ValueError as e:
                raise RuntimeError(f"Level 2 error: {str(e)}")

        def level_1_function():
            try:
                level_2_function()
            except RuntimeError as e:
                raise Exception(f"Level 1 error: {str(e)}")

        # Kaskad hata uygun şekilde işlenmeli
        with pytest.raises(Exception) as exc_info:
            level_1_function()

        assert "Level 1 error" in str(exc_info.value)
        assert "Level 2 error" in str(exc_info.value)
        assert "Level 3 error" in str(exc_info.value)

    def test_graceful_degradation(self):
        """Graceful degradation testi"""

        def primary_service():
            raise Exception("Primary service unavailable")

        def fallback_service():
            return "Fallback response"

        def service_with_fallback():
            try:
                return primary_service()
            except Exception:
                return fallback_service()

        # Primary service başarısız olduğunda fallback çalışmalı
        result = service_with_fallback()
        assert result == "Fallback response"

    def test_error_recovery(self):
        """Hata kurtarma testi"""

        class ServiceWithRetry:
            def __init__(self):
                self.attempts = 0

            def operation(self):
                self.attempts += 1
                if self.attempts < 3:
                    raise Exception("Temporary failure")
                return "Success"

            def execute_with_retry(self, max_attempts=3):
                for attempt in range(max_attempts):
                    try:
                        return self.operation()
                    except Exception as e:
                        if attempt == max_attempts - 1:
                            raise e
                        continue

        service = ServiceWithRetry()
        result = service.execute_with_retry()
        assert result == "Success"
        assert service.attempts == 3

    def test_error_notification(self):
        """Hata bildirimi testi"""

        class ErrorNotifier:
            def __init__(self):
                self.notifications = []

            def notify_error(self, error, context):
                notification = {
                    "error": str(error),
                    "context": context,
                    "timestamp": "2024-01-01T00:00:00Z",
                }
                self.notifications.append(notification)
                return True

        notifier = ErrorNotifier()

        try:
            raise Exception("Test error")
        except Exception as e:
            notifier.notify_error(e, "test_context")

        assert len(notifier.notifications) == 1
        assert notifier.notifications[0]["error"] == "Test error"
        assert notifier.notifications[0]["context"] == "test_context"

    def test_error_metrics_collection(self):
        """Hata metrikleri toplama testi"""

        class ErrorMetrics:
            def __init__(self):
                self.error_counts = {}

            def record_error(self, error_type):
                self.error_counts[error_type] = self.error_counts.get(error_type, 0) + 1

            def get_error_stats(self):
                return self.error_counts

        metrics = ErrorMetrics()

        # Farklı hata türlerini kaydet
        for _ in range(3):
            metrics.record_error("database_error")

        for _ in range(2):
            metrics.record_error("validation_error")

        stats = metrics.get_error_stats()
        assert stats["database_error"] == 3
        assert stats["validation_error"] == 2
